<robot
  name="Poppy_Torso_Gripper_Final_updated">
  <link
    name="base_link">
    <inertial>
      <origin
        xyz="-0.0021191 -0.01235 -0.069838"
        rpy="0 0 0" />
      <mass
        value="0.31973" />
      <inertia
        ixx="0.00047414"
        ixy="-4.0188E-06"
        ixz="-3.9103E-06"
        iyy="0.00045154"
        iyz="-2.2795E-05"
        izz="0.00051844" />
    </inertial>
    <visual>
      <origin
        xyz="0 0 0"
        rpy="0 0 0" />
      <geometry>
        <mesh
          filename="../meshes/base_link.STL" />
      </geometry>
      <material
        name="">
        <color
          rgba="0.79608 0.82353 0.93725 1" />
      </material>
    </visual>
    <collision>
      <origin
        xyz="0 0 0"
        rpy="0 0 0" />
      <geometry>
        <mesh
          filename="../meshes/base_link.STL" />
      </geometry>
    </collision>
  </link>
  <link
    name="spine">
    <inertial>
      <origin
        xyz="1.333E-07 -0.0095429 0.025945"
        rpy="0 0 0" />
      <mass
        value="0.065098" />
      <inertia
        ixx="3.0923E-05"
        ixy="-2.4051E-10"
        ixz="-1.0699E-09"
        iyy="2.8821E-05"
        iyz="-2.0318E-06"
        izz="2.1564E-05" />
    </inertial>
    <visual>
      <origin
        xyz="0 0 0"
        rpy="0 0 0" />
      <geometry>
        <mesh
          filename="../meshes/spine.STL" />
      </geometry>
      <material
        name="">
        <color
          rgba="0.79216 0.81961 0.93333 1" />
      </material>
    </visual>
    <collision>
      <origin
        xyz="0 0 0"
        rpy="0 0 0" />
      <geometry>
        <mesh
          filename="../meshes/spine.STL" />
      </geometry>
    </collision>
  </link>
  <joint
    name="base_joint_self_defined"
    type="revolute">
    <origin
      xyz="0 0 0"
      rpy="-1.8864E-16 -1.3878E-17 0" />
    <parent
      link="base_link" />
    <child
      link="spine" />
    <axis
      xyz="0 0 1" />
    <limit
      effort="0"
      velocity="0" />
  </joint>
  <link
    name="chest_side">
    <inertial>
      <origin
        xyz="-0.01475 -0.0097074 -0.00013703"
        rpy="0 0 0" />
      <mass
        value="0.11037" />
      <inertia
        ixx="3.0135E-05"
        ixy="-2.7791E-06"
        ixz="2.2309E-07"
        iyy="6.4336E-05"
        iyz="-6.5672E-08"
        izz="7.03E-05" />
    </inertial>
    <visual>
      <origin
        xyz="0 0 0"
        rpy="0 0 0" />
      <geometry>
        <mesh
          filename="../meshes/chest_side.STL" />
      </geometry>
      <material
        name="">
        <color
          rgba="0.8902 0.91373 0.92941 1" />
      </material>
    </visual>
    <collision>
      <origin
        xyz="0 0 0"
        rpy="0 0 0" />
      <geometry>
        <mesh
          filename="../meshes/chest_side.STL" />
      </geometry>
    </collision>
  </link>
  <joint
    name="chest_side_joint"
    type="revolute">
    <origin
      xyz="0 0.0028 0.0745"
      rpy="-1.5708 -1.8864E-16 1.5708" />
    <parent
      link="spine" />
    <child
      link="chest_side" />
    <axis
      xyz="0 0 1" />
    <limit
      effort="0"
      velocity="0" />
  </joint>
  <link
    name="chest_front">
    <inertial>
      <origin
        xyz="0.051628 -1.3986E-06 -0.012069"
        rpy="0 0 0" />
      <mass
        value="0.21242" />
      <inertia
        ixx="0.00054836"
        ixy="2.6788E-08"
        ixz="-1.7626E-06"
        iyy="0.00015279"
        iyz="-2.389E-08"
        izz="0.00048633" />
    </inertial>
    <visual>
      <origin
        xyz="0 0 0"
        rpy="0 0 0" />
      <geometry>
        <mesh
          filename="../meshes/chest_front.STL" />
      </geometry>
      <material
        name="">
        <color
          rgba="1 1 1 0.32" />
      </material>
    </visual>
    <collision>
      <origin
        xyz="0 0 0"
        rpy="0 0 0" />
      <geometry>
        <mesh
          filename="../meshes/chest_front.STL" />
      </geometry>
    </collision>
  </link>
  <joint
    name="chest_front_joint"
    type="revolute">
    <origin
      xyz="0 0 0"
      rpy="-1.5708 2.7756E-16 -1.5708" />
    <parent
      link="chest_side" />
    <child
      link="chest_front" />
    <axis
      xyz="0 0 1" />
    <limit
      effort="0"
      velocity="0" />
  </joint>
  <link
    name="left_shoulder">
    <inertial>
      <origin
        xyz="-0.0091594 -0.001817 0.0090584"
        rpy="0 0 0" />
      <mass
        value="0.0096453" />
      <inertia
        ixx="2.1053E-06"
        ixy="1.1061E-08"
        ixz="-3.3944E-08"
        iyy="4.0656E-06"
        iyz="-5.4424E-08"
        izz="3.8816E-06" />
    </inertial>
    <visual>
      <origin
        xyz="0 0 0"
        rpy="0 0 0" />
      <geometry>
        <mesh
          filename="../meshes/left_shoulder.STL" />
      </geometry>
      <material
        name="">
        <color
          rgba="0.79608 0.82353 0.93725 1" />
      </material>
    </visual>
    <collision>
      <origin
        xyz="0 0 0"
        rpy="0 0 0" />
      <geometry>
        <mesh
          filename="../meshes/left_shoulder.STL" />
      </geometry>
    </collision>
  </link>
  <joint
    name="left_shoulder_joint"
    type="revolute">
    <origin
      xyz="0.05 -0.0785 0.004"
      rpy="1.5708 4.9266E-16 -2.7756E-16" />
    <parent
      link="chest_front" />
    <child
      link="left_shoulder" />
    <axis
      xyz="0 0 1" />
    <limit
      effort="0"
      velocity="0" />
  </joint>
  <link
    name="left_shoulder2">
    <inertial>
      <origin
        xyz="-5.13E-07 0.013997 -0.0090144"
        rpy="0 0 0" />
      <mass
        value="0.056082" />
      <inertia
        ixx="2.0093E-05"
        ixy="1.5615E-10"
        ixz="-1.1504E-09"
        iyy="1.1524E-05"
        iyz="3.1077E-07"
        izz="1.693E-05" />
    </inertial>
    <visual>
      <origin
        xyz="0 0 0"
        rpy="0 0 0" />
      <geometry>
        <mesh
          filename="../meshes/left_shoulder2.STL" />
      </geometry>
      <material
        name="">
        <color
          rgba="1 1 1 0.32" />
      </material>
    </visual>
    <collision>
      <origin
        xyz="0 0 0"
        rpy="0 0 0" />
      <geometry>
        <mesh
          filename="../meshes/left_shoulder2.STL" />
      </geometry>
    </collision>
  </link>
  <joint
    name="left_shoulder2_joint"
    type="revolute">
    <origin
      xyz="0 0 0.027"
      rpy="1.5708 -1.6653E-16 1.5708" />
    <parent
      link="left_shoulder" />
    <child
      link="left_shoulder2" />
    <axis
      xyz="0 0 1" />
    <limit
      effort="0"
      velocity="0" />
  </joint>
  <link
    name="left_elbow">
    <inertial>
      <origin
        xyz="0.0001344 -0.010734 0.058098"
        rpy="0 0 0" />
      <mass
        value="0.11268" />
      <inertia
        ixx="0.0001848"
        ixy="-1.146E-08"
        ixz="-5.1799E-07"
        iyy="0.00018114"
        iyz="-2.6806E-06"
        izz="3.1436E-05" />
    </inertial>
    <visual>
      <origin
        xyz="0 0 0"
        rpy="0 0 0" />
      <geometry>
        <mesh
          filename="../meshes/left_elbow.STL" />
      </geometry>
      <material
        name="">
        <color
          rgba="0.79216 0.81961 0.93333 1" />
      </material>
    </visual>
    <collision>
      <origin
        xyz="0 0 0"
        rpy="0 0 0" />
      <geometry>
        <mesh
          filename="../meshes/left_elbow.STL" />
      </geometry>
    </collision>
  </link>
  <joint
    name="left_elbow_joint"
    type="revolute">
    <origin
      xyz="0 0.0426 -0.0185"
      rpy="-1.5708 -2.2551E-16 0" />
    <parent
      link="left_shoulder2" />
    <child
      link="left_elbow" />
    <axis
      xyz="0 0 1" />
    <limit
      effort="0"
      velocity="0" />
  </joint>
  <link
    name="left_elbow2">
    <inertial>
      <origin
        xyz="-0.0047314 -0.13471 -0.0050309"
        rpy="0 0 0" />
      <mass
        value="0.12463" />
      <inertia
        ixx="0.00039768"
        ixy="1.6633E-05"
        ixz="1.3429E-06"
        iyy="4.5267E-05"
        iyz="1.8683E-05"
        izz="0.00037494" />
    </inertial>
    <visual>
      <origin
        xyz="0 0 0"
        rpy="0 0 0" />
      <geometry>
        <mesh
          filename="../meshes/left_elbow2.STL" />
      </geometry>
      <material
        name="">
        <color
          rgba="0.79608 0.82353 0.93725 1" />
      </material>
    </visual>
    <collision>
      <origin
        xyz="0 0 0"
        rpy="0 0 0" />
      <geometry>
        <mesh
          filename="../meshes/left_elbow2.STL" />
      </geometry>
    </collision>
  </link>
  <joint
    name="left_elbow2_joint"
    type="revolute">
    <origin
      xyz="0 -0.01 0.1064"
      rpy="-1.5708 -4.4409E-16 -1.5708" />
    <parent
      link="left_elbow" />
    <child
      link="left_elbow2" />
    <axis
      xyz="0 0 1" />
    <limit
      effort="0"
      velocity="0" />
  </joint>
  <link
    name="left_wrist">
    <inertial>
      <origin
        xyz="0.066452 0.0053235 -0.018451"
        rpy="0 0 0" />
      <mass
        value="0.071598" />
      <inertia
        ixx="4.2309E-05"
        ixy="2.4235E-05"
        ixz="2.6597E-09"
        iyy="0.00010859"
        iyz="5.3397E-10"
        izz="0.00011611" />
    </inertial>
    <visual>
      <origin
        xyz="0 0 0"
        rpy="0 0 0" />
      <geometry>
        <mesh
          filename="../meshes/left_wrist.STL" />
      </geometry>
      <material
        name="">
        <color
          rgba="0.79608 0.82353 0.93725 1" />
      </material>
    </visual>
    <collision>
      <origin
        xyz="0 0 0"
        rpy="0 0 0" />
      <geometry>
        <mesh
          filename="../meshes/left_wrist.STL" />
      </geometry>
    </collision>
  </link>
  <joint
    name="left_wrist_joint"
    type="revolute">
    <origin
      xyz="0.016941 -0.141 -0.02248"
      rpy="-1.5708 1.6653E-16 -1.5708" />
    <parent
      link="left_elbow2" />
    <child
      link="left_wrist" />
    <axis
      xyz="0 0 1" />
    <limit
      effort="0"
      velocity="0" />
  </joint>
  <link
    name="right_shoulder">
    <inertial>
      <origin
        xyz="-0.0091524 -0.0018163 -0.0090584"
        rpy="0 0 0" />
      <mass
        value="0.0096454" />
      <inertia
        ixx="2.1055E-06"
        ixy="1.0201E-08"
        ixz="3.3556E-08"
        iyy="4.0651E-06"
        iyz="5.4405E-08"
        izz="3.8813E-06" />
    </inertial>
    <visual>
      <origin
        xyz="0 0 0"
        rpy="0 0 0" />
      <geometry>
        <mesh
          filename="../meshes/right_shoulder.STL" />
      </geometry>
      <material
        name="">
        <color
          rgba="0.79608 0.82353 0.93725 1" />
      </material>
    </visual>
    <collision>
      <origin
        xyz="0 0 0"
        rpy="0 0 0" />
      <geometry>
        <mesh
          filename="../meshes/right_shoulder.STL" />
      </geometry>
    </collision>
  </link>
  <joint
    name="right_shoulder_joint"
    type="revolute">
    <origin
      xyz="0.05 0.0785 0.004"
      rpy="1.5708 1.6653E-16 -2.7756E-16" />
    <parent
      link="chest_front" />
    <child
      link="right_shoulder" />
    <axis
      xyz="0 0 1" />
    <limit
      effort="0"
      velocity="0" />
  </joint>
  <link
    name="right_shoulder2">
    <inertial>
      <origin
        xyz="5.13E-07 -0.013997 -0.0090144"
        rpy="0 0 0" />
      <mass
        value="0.056082" />
      <inertia
        ixx="2.0093E-05"
        ixy="1.5615E-10"
        ixz="1.1504E-09"
        iyy="1.1524E-05"
        iyz="-3.1077E-07"
        izz="1.693E-05" />
    </inertial>
    <visual>
      <origin
        xyz="0 0 0"
        rpy="0 0 0" />
      <geometry>
        <mesh
          filename="../meshes/right_shoulder2.STL" />
      </geometry>
      <material
        name="">
        <color
          rgba="1 1 1 0.32" />
      </material>
    </visual>
    <collision>
      <origin
        xyz="0 0 0"
        rpy="0 0 0" />
      <geometry>
        <mesh
          filename="../meshes/right_shoulder2.STL" />
      </geometry>
    </collision>
  </link>
  <joint
    name="right_shoulder2_joint"
    type="revolute">
    <origin
      xyz="0 0 -0.027"
      rpy="1.5708 5.5511E-17 1.5708" />
    <parent
      link="right_shoulder" />
    <child
      link="right_shoulder2" />
    <axis
      xyz="0 0 1" />
    <limit
      effort="0"
      velocity="0" />
  </joint>
  <link
    name="right_elbow">
    <inertial>
      <origin
        xyz="0.00013405 -0.010734 -0.058098"
        rpy="0 0 0" />
      <mass
        value="0.11268" />
      <inertia
        ixx="0.0001848"
        ixy="-1.0749E-08"
        ixz="5.1811E-07"
        iyy="0.00018114"
        iyz="2.6806E-06"
        izz="3.1436E-05" />
    </inertial>
    <visual>
      <origin
        xyz="0 0 0"
        rpy="0 0 0" />
      <geometry>
        <mesh
          filename="../meshes/right_elbow.STL" />
      </geometry>
      <material
        name="">
        <color
          rgba="0.79608 0.82353 0.93725 1" />
      </material>
    </visual>
    <collision>
      <origin
        xyz="0 0 0"
        rpy="0 0 0" />
      <geometry>
        <mesh
          filename="../meshes/right_elbow.STL" />
      </geometry>
    </collision>
  </link>
  <joint
    name="right_elbow_joint"
    type="revolute">
    <origin
      xyz="0 -0.0426 -0.0185"
      rpy="-1.5708 2.2204E-16 1.9429E-16" />
    <parent
      link="right_shoulder2" />
    <child
      link="right_elbow" />
    <axis
      xyz="0 0 1" />
    <limit
      effort="0"
      velocity="0" />
  </joint>
  <link
    name="right_elbow2">
    <inertial>
      <origin
        xyz="-0.0034087 0.13471 -0.0050307"
        rpy="0 0 0" />
      <mass
        value="0.12462" />
      <inertia
        ixx="0.00039768"
        ixy="-2.1262E-05"
        ixz="7.2639E-07"
        iyy="4.5704E-05"
        iyz="-1.868E-05"
        izz="0.00037538" />
    </inertial>
    <visual>
      <origin
        xyz="0 0 0"
        rpy="0 0 0" />
      <geometry>
        <mesh
          filename="../meshes/right_elbow2.STL" />
      </geometry>
      <material
        name="">
        <color
          rgba="0.79608 0.82353 0.93725 1" />
      </material>
    </visual>
    <collision>
      <origin
        xyz="0 0 0"
        rpy="0 0 0" />
      <geometry>
        <mesh
          filename="../meshes/right_elbow2.STL" />
      </geometry>
    </collision>
  </link>
  <joint
    name="right_elbow2_joint"
    type="revolute">
    <origin
      xyz="0 -0.01 -0.1064"
      rpy="-1.5708 1.6653E-16 -1.5708" />
    <parent
      link="right_elbow" />
    <child
      link="right_elbow2" />
    <axis
      xyz="0 0 1" />
    <limit
      effort="0"
      velocity="0" />
  </joint>
  <link
    name="right_wrist">
    <inertial>
      <origin
        xyz="-0.066452 0.0053234 0.018451"
        rpy="0 0 0" />
      <mass
        value="0.071597" />
      <inertia
        ixx="4.2308E-05"
        ixy="-2.4234E-05"
        ixz="2.7298E-09"
        iyy="0.00010859"
        iyz="-4.9221E-10"
        izz="0.00011611" />
    </inertial>
    <visual>
      <origin
        xyz="0 0 0"
        rpy="0 0 0" />
      <geometry>
        <mesh
          filename="../meshes/right_wrist.STL" />
      </geometry>
      <material
        name="">
        <color
          rgba="0.79608 0.82353 0.93725 1" />
      </material>
    </visual>
    <collision>
      <origin
        xyz="0 0 0"
        rpy="0 0 0" />
      <geometry>
        <mesh
          filename="../meshes/right_wrist.STL" />
      </geometry>
    </collision>
  </link>
  <joint
    name="right_wrist_joint"
    type="revolute">
    <origin
      xyz="-0.022439 0.141 -0.02248"
      rpy="-1.5708 -2.7756E-16 -1.5708" />
    <parent
      link="right_elbow2" />
    <child
      link="right_wrist" />
    <axis
      xyz="0 0 1" />
    <limit
      effort="0"
      velocity="0" />
  </joint>
  <link
    name="neck">
    <inertial>
      <origin
        xyz="-0.0014749 -2.2974E-05 0.0093446"
        rpy="0 0 0" />
      <mass
        value="0.0067709" />
      <inertia
        ixx="8.3483E-07"
        ixy="2.3176E-10"
        ixz="1.0699E-07"
        iyy="2.9614E-06"
        iyz="1.7877E-11"
        izz="2.6869E-06" />
    </inertial>
    <visual>
      <origin
        xyz="0 0 0"
        rpy="0 0 0" />
      <geometry>
        <mesh
          filename="../meshes/neck.STL" />
      </geometry>
      <material
        name="">
        <color
          rgba="0.79608 0.82353 0.93725 1" />
      </material>
    </visual>
    <collision>
      <origin
        xyz="0 0 0"
        rpy="0 0 0" />
      <geometry>
        <mesh
          filename="../meshes/neck.STL" />
      </geometry>
    </collision>
  </link>
  <joint
    name="neck_joint"
    type="revolute">
    <origin
      xyz="0.08394 0 0.0049799"
      rpy="-1.5708 2.2204E-16 -1.5708" />
    <parent
      link="chest_front" />
    <child
      link="neck" />
    <axis
      xyz="0 0 1" />
    <limit
      effort="0"
      velocity="0" />
  </joint>
  <link
    name="head">
    <inertial>
      <origin
        xyz="-0.023514 -0.027388 -7.2524E-05"
        rpy="0 0 0" />
      <mass
        value="0.21632" />
      <inertia
        ixx="0.0004538"
        ixy="-2.2514E-05"
        ixz="-2.5444E-06"
        iyy="0.00047362"
        iyz="-3.328E-07"
        izz="0.00040168" />
    </inertial>
    <visual>
      <origin
        xyz="0 0 0"
        rpy="0 0 0" />
      <geometry>
        <mesh
          filename="../meshes/head.STL" />
      </geometry>
      <material
        name="">
        <color
          rgba="0.79608 0.82353 0.93725 1" />
      </material>
    </visual>
    <collision>
      <origin
        xyz="0 0 0"
        rpy="0 0 0" />
      <geometry>
        <mesh
          filename="../meshes/head.STL" />
      </geometry>
    </collision>
  </link>
  <joint
    name="head_link"
    type="revolute">
    <origin
      xyz="0 -2.0077E-05 0.02006"
      rpy="-1.5708 2.2072E-16 -1.5708" />
    <parent
      link="neck" />
    <child
      link="head" />
    <axis
      xyz="0 0 1" />
    <limit
      effort="0"
      velocity="0" />
  </joint>
</robot>