<robot
  name="poppy_torso_v2.urdf">
  <link
    name="base_link">
    <inertial>
      <origin
        xyz="-0.0041533 -0.011822 -0.069838"
        rpy="0 0 0" />
      <mass
        value="0.31973" />
      <inertia
        ixx="0.00047219"
        ixy="-7.5186E-06"
        ixz="-7.6648E-06"
        iyy="0.0004535"
        iyz="-2.1821E-05"
        izz="0.00051844" />
    </inertial>
    <visual>
      <origin
        xyz="0 0 0"
        rpy="0 0 0" />
      <geometry>
        <mesh
          filename="package://poppy_torso_v2.urdf/meshes/base_link.STL" />
      </geometry>
      <material
        name="">
        <color
          rgba="0.79608 0.82353 0.93725 1" />
      </material>
    </visual>
    <collision>
      <origin
        xyz="0 0 0"
        rpy="0 0 0" />
      <geometry>
        <mesh
          filename="package://poppy_torso_v2.urdf/meshes/base_link.STL" />
      </geometry>
    </collision>
  </link>
  <link
    name="spine">
    <inertial>
      <origin
        xyz="1.3311E-07 -0.0095429 0.025945"
        rpy="0 0 0" />
      <mass
        value="0.065098" />
      <inertia
        ixx="3.0923E-05"
        ixy="-2.4156E-10"
        ixz="-1.0697E-09"
        iyy="2.8821E-05"
        iyz="-2.0318E-06"
        izz="2.1564E-05" />
    </inertial>
    <visual>
      <origin
        xyz="0 0 0"
        rpy="0 0 0" />
      <geometry>
        <mesh
          filename="package://poppy_torso_v2.urdf/meshes/spine.STL" />
      </geometry>
      <material
        name="">
        <color
          rgba="0.79216 0.81961 0.93333 1" />
      </material>
    </visual>
    <collision>
      <origin
        xyz="0 0 0"
        rpy="0 0 0" />
      <geometry>
        <mesh
          filename="package://poppy_torso_v2.urdf/meshes/spine.STL" />
      </geometry>
    </collision>
  </link>
  <joint
    name="base_joint_self_defined"
    type="revolute">
    <origin
      xyz="0 0 0"
      rpy="-1.8864E-16 -3.0815E-33 0" />
    <parent
      link="base_link" />
    <child
      link="spine" />
    <axis
      xyz="0 0 1" />
    <limit
      effort="0"
      velocity="0" />
  </joint>
  <link
    name="chest_side">
    <inertial>
      <origin
        xyz="-0.01475 -0.0097074 -0.00013703"
        rpy="0 0 0" />
      <mass
        value="0.11037" />
      <inertia
        ixx="3.0135E-05"
        ixy="-2.7791E-06"
        ixz="2.2309E-07"
        iyy="6.4336E-05"
        iyz="-6.5673E-08"
        izz="7.03E-05" />
    </inertial>
    <visual>
      <origin
        xyz="0 0 0"
        rpy="0 0 0" />
      <geometry>
        <mesh
          filename="package://poppy_torso_v2.urdf/meshes/chest_side.STL" />
      </geometry>
      <material
        name="">
        <color
          rgba="0.8902 0.91373 0.92941 1" />
      </material>
    </visual>
    <collision>
      <origin
        xyz="0 0 0"
        rpy="0 0 0" />
      <geometry>
        <mesh
          filename="package://poppy_torso_v2.urdf/meshes/chest_side.STL" />
      </geometry>
    </collision>
  </link>
  <joint
    name="chest_side_joint"
    type="revolute">
    <origin
      xyz="0 0.0028 0.0745"
      rpy="-1.5708 -1.8864E-16 1.5708" />
    <parent
      link="spine" />
    <child
      link="chest_side" />
    <axis
      xyz="0 0 1" />
    <limit
      effort="0"
      velocity="0" />
  </joint>
  <link
    name="chest_front">
    <inertial>
      <origin
        xyz="0.0516284389564179 -1.56640966363672E-06 -0.0120687564654568"
        rpy="0 0 0" />
      <mass
        value="0.212413185651446" />
      <inertia
        ixx="0.000548350920248042"
        ixy="2.6540085531893E-08"
        ixz="-1.76102337332712E-06"
        iyy="0.000152789180532871"
        iyz="-2.66047588384351E-08"
        izz="0.00048632340178832" />
    </inertial>
    <visual>
      <origin
        xyz="0 0 0"
        rpy="0 0 0" />
      <geometry>
        <mesh
          filename="package://poppy_torso_v2.urdf/meshes/chest_front.STL" />
      </geometry>
      <material
        name="">
        <color
          rgba="1 1 1 0.32" />
      </material>
    </visual>
    <collision>
      <origin
        xyz="0 0 0"
        rpy="0 0 0" />
      <geometry>
        <mesh
          filename="package://poppy_torso_v2.urdf/meshes/chest_front.STL" />
      </geometry>
    </collision>
  </link>
  <joint
    name="chest_front_joint"
    type="revolute">
    <origin
      xyz="0 0 0"
      rpy="-1.5707963267949 2.77555756156289E-16 -1.5707963267949" />
    <parent
      link="chest_side" />
    <child
      link="chest_front" />
    <axis
      xyz="0 0 1" />
  </joint>
  <link
    name="left_shoulder">
    <inertial>
      <origin
        xyz="-0.0091594 -0.001817 0.0090585"
        rpy="0 0 0" />
      <mass
        value="0.0096453" />
      <inertia
        ixx="2.1053E-06"
        ixy="1.1062E-08"
        ixz="-3.3945E-08"
        iyy="4.0656E-06"
        iyz="-5.4424E-08"
        izz="3.8816E-06" />
    </inertial>
    <visual>
      <origin
        xyz="0 0 0"
        rpy="0 0 0" />
      <geometry>
        <mesh
          filename="package://poppy_torso_v2.urdf/meshes/left_shoulder.STL" />
      </geometry>
      <material
        name="">
        <color
          rgba="0.79608 0.82353 0.93725 1" />
      </material>
    </visual>
    <collision>
      <origin
        xyz="0 0 0"
        rpy="0 0 0" />
      <geometry>
        <mesh
          filename="package://poppy_torso_v2.urdf/meshes/left_shoulder.STL" />
      </geometry>
    </collision>
  </link>
  <joint
    name="left_shoulder_joint"
    type="revolute">
    <origin
      xyz="0.05 -0.0785 0.004"
      rpy="1.5708 4.9266E-16 -2.7756E-16" />
    <parent
      link="chest_front" />
    <child
      link="left_shoulder" />
    <axis
      xyz="0 0 1" />
    <limit
      effort="0"
      velocity="0" />
  </joint>
  <link
    name="left_shoulder2">
    <inertial>
      <origin
        xyz="-5.12916590644785E-07 0.013997092641807 -0.00901440721895361"
        rpy="0 0 0" />
      <mass
        value="0.0560816261526276" />
      <inertia
        ixx="2.00926661196522E-05"
        ixy="1.56156233554937E-10"
        ixz="-1.15054193426798E-09"
        iyy="1.15236600129741E-05"
        iyz="3.10765359223322E-07"
        izz="1.69300488718864E-05" />
    </inertial>
    <visual>
      <origin
        xyz="0 0 0"
        rpy="0 0 0" />
      <geometry>
        <mesh
          filename="package://poppy_torso_v2.urdf/meshes/left_shoulder2.STL" />
      </geometry>
      <material
        name="">
        <color
          rgba="1 1 1 0.32" />
      </material>
    </visual>
    <collision>
      <origin
        xyz="0 0 0"
        rpy="0 0 0" />
      <geometry>
        <mesh
          filename="package://poppy_torso_v2.urdf/meshes/left_shoulder2.STL" />
      </geometry>
    </collision>
  </link>
  <joint
    name="left_shoulder2_joint"
    type="revolute">
    <origin
      xyz="0 0 0.027"
      rpy="1.5707963267949 -1.66533453693773E-16 1.5707963267949" />
    <parent
      link="left_shoulder" />
    <child
      link="left_shoulder2" />
    <axis
      xyz="0 0 1" />
  </joint>
  <link
    name="left_elbow">
    <inertial>
      <origin
        xyz="0.000134407661343691 -0.010734205757447 0.0580980424897709"
        rpy="0 0 0" />
      <mass
        value="0.112675711717156" />
      <inertia
        ixx="0.000184799927907011"
        ixy="-1.14534033979207E-08"
        ixz="-5.18008257730129E-07"
        iyy="0.000181143017641689"
        iyz="-2.68067658529521E-06"
        izz="3.1435947223255E-05" />
    </inertial>
    <visual>
      <origin
        xyz="0 0 0"
        rpy="0 0 0" />
      <geometry>
        <mesh
          filename="package://poppy_torso_v2.urdf/meshes/left_elbow.STL" />
      </geometry>
      <material
        name="">
        <color
          rgba="0.792156862745098 0.819607843137255 0.933333333333333 1" />
      </material>
    </visual>
    <collision>
      <origin
        xyz="0 0 0"
        rpy="0 0 0" />
      <geometry>
        <mesh
          filename="package://poppy_torso_v2.urdf/meshes/left_elbow.STL" />
      </geometry>
    </collision>
  </link>
  <joint
    name="left_elbow_joint"
    type="revolute">
    <origin
      xyz="0 0.0426 -0.0185"
      rpy="-1.5708 -2.2551E-16 0" />
    <parent
      link="left_shoulder2" />
    <child
      link="left_elbow" />
    <axis
      xyz="0 0 1" />
    <limit
      effort="0"
      velocity="0" />
  </joint>
  <link
    name="left_elbow2">
    <inertial>
      <origin
        xyz="-0.00473150125050945 -0.134709050839495 -0.00503103911482908"
        rpy="0 0 0" />
      <mass
        value="0.124627257833673" />
      <inertia
        ixx="0.000397679948700664"
        ixy="1.66342227382365E-05"
        ixz="1.34262232458893E-06"
        iyy="4.52674117747585E-05"
        iyz="1.86836280303593E-05"
        izz="0.000374943341565953" />
    </inertial>
    <visual>
      <origin
        xyz="0 0 0"
        rpy="0 0 0" />
      <geometry>
        <mesh
          filename="package://poppy_torso_v2.urdf/meshes/left_elbow2.STL" />
      </geometry>
      <material
        name="">
        <color
          rgba="0.796078431372549 0.823529411764706 0.937254901960784 1" />
      </material>
    </visual>
    <collision>
      <origin
        xyz="0 0 0"
        rpy="0 0 0" />
      <geometry>
        <mesh
          filename="package://poppy_torso_v2.urdf/meshes/left_elbow2.STL" />
      </geometry>
    </collision>
  </link>
  <joint
    name="left_elbow2_joint"
    type="revolute">
    <origin
      xyz="0 -0.01 0.1064"
      rpy="-1.5708 -4.4409E-16 -1.5708" />
    <parent
      link="left_elbow" />
    <child
      link="left_elbow2" />
    <axis
      xyz="0 0 1" />
    <limit
      effort="0"
      velocity="0" />
  </joint>
  <link
    name="left_wrist">
    <inertial>
      <origin
        xyz="0.0642528617533991 0.0177837831183665 -0.0184512377006541"
        rpy="0 0 0" />
      <mass
        value="0.0715967003704915" />
      <inertia
        ixx="3.56821714348092E-05"
        ixy="1.02048554563415E-05"
        ixz="2.67338360131052E-09"
        iyy="0.000115214288288214"
        iyz="8.48128625532804E-10"
        izz="0.000116111001814172" />
    </inertial>
    <visual>
      <origin
        xyz="0 0 0"
        rpy="0 0 0" />
      <geometry>
        <mesh
          filename="package://poppy_torso_v2.urdf/meshes/left_wrist.STL" />
      </geometry>
      <material
        name="">
        <color
          rgba="0.796078431372549 0.823529411764706 0.937254901960784 1" />
      </material>
    </visual>
    <collision>
      <origin
        xyz="0 0 0"
        rpy="0 0 0" />
      <geometry>
        <mesh
          filename="package://poppy_torso_v2.urdf/meshes/left_wrist.STL" />
      </geometry>
    </collision>
  </link>
  <joint
    name="left_wrist_joint"
    type="revolute">
    <origin
      xyz="0.0169413570698455 -0.141000000000007 -0.0224799225014185"
      rpy="-1.5707963267949 1.66533453693773E-16 -1.5707963267949" />
    <parent
      link="left_elbow2" />
    <child
      link="left_wrist" />
    <axis
      xyz="0 0 1" />
  </joint>
  <link
    name="left_end_effector" />
  <joint
    name="left_end_effector_joint"
    type="fixed">
    <origin
      xyz="0.082791 -0.02673 -0.02124"
      rpy="-1.5708 -1.301E-18 0" />
    <parent
      link="left_wrist" />
    <child
      link="left_end_effector" />
    <axis
      xyz="0 0 0" />
  </joint>
  <link
    name="right_shoulder">
    <inertial>
      <origin
        xyz="-0.00915239215466135 -0.00181626859785421 -0.00905843310136317"
        rpy="0 0 0" />
      <mass
        value="0.00964541698737779" />
      <inertia
        ixx="2.10548662935362E-06"
        ixy="1.02029692239802E-08"
        ixz="3.3555899928789E-08"
        iyy="4.06513535627495E-06"
        iyz="5.44036257258871E-08"
        izz="3.88132818879036E-06" />
    </inertial>
    <visual>
      <origin
        xyz="0 0 0"
        rpy="0 0 0" />
      <geometry>
        <mesh
          filename="package://poppy_torso_v2.urdf/meshes/right_shoulder.STL" />
      </geometry>
      <material
        name="">
        <color
          rgba="0.796078431372549 0.823529411764706 0.937254901960784 1" />
      </material>
    </visual>
    <collision>
      <origin
        xyz="0 0 0"
        rpy="0 0 0" />
      <geometry>
        <mesh
          filename="package://poppy_torso_v2.urdf/meshes/right_shoulder.STL" />
      </geometry>
    </collision>
  </link>
  <joint
    name="right_shoulder_joint"
    type="revolute">
    <origin
      xyz="0.05 0.0784999999999999 0.00400000000000002"
      rpy="1.5707963267949 1.66533453693773E-16 -2.77555756156289E-16" />
    <parent
      link="chest_front" />
    <child
      link="right_shoulder" />
    <axis
      xyz="0 0 1" />
  </joint>
  <link
    name="right_shoulder2">
    <inertial>
      <origin
        xyz="5.12916757067217E-07 -0.0139970926437282 -0.00901440721797267"
        rpy="0 0 0" />
      <mass
        value="0.05608162614809" />
      <inertia
        ixx="2.0092666116493E-05"
        ixy="1.56155941852249E-10"
        ixz="1.1505420454443E-09"
        iyy="1.15236600122213E-05"
        iyz="-3.10765360660004E-07"
        izz="1.69300488694267E-05" />
    </inertial>
    <visual>
      <origin
        xyz="0 0 0"
        rpy="0 0 0" />
      <geometry>
        <mesh
          filename="package://poppy_torso_v2.urdf/meshes/right_shoulder2.STL" />
      </geometry>
      <material
        name="">
        <color
          rgba="1 1 1 0.32" />
      </material>
    </visual>
    <collision>
      <origin
        xyz="0 0 0"
        rpy="0 0 0" />
      <geometry>
        <mesh
          filename="package://poppy_torso_v2.urdf/meshes/right_shoulder2.STL" />
      </geometry>
    </collision>
  </link>
  <joint
    name="right_shoulder2_joint"
    type="revolute">
    <origin
      xyz="0 0 -0.027"
      rpy="1.5707963267949 5.55111512312578E-17 1.5707963267949" />
    <parent
      link="right_shoulder" />
    <child
      link="right_shoulder2" />
    <axis
      xyz="0 0 1" />
  </joint>
  <link
    name="right_elbow">
    <inertial>
      <origin
        xyz="0.000134050057090468 -0.0107342047568474 -0.0580980456796688"
        rpy="0 0 0" />
      <mass
        value="0.112675723709005" />
      <inertia
        ixx="0.000184799941144802"
        ixy="-1.07553437665916E-08"
        ixz="5.1808697575707E-07"
        iyy="0.000181143041569846"
        iyz="2.6806833596721E-06"
        izz="3.14359602663305E-05" />
    </inertial>
    <visual>
      <origin
        xyz="0 0 0"
        rpy="0 0 0" />
      <geometry>
        <mesh
          filename="package://poppy_torso_v2.urdf/meshes/right_elbow.STL" />
      </geometry>
      <material
        name="">
        <color
          rgba="0.796078431372549 0.823529411764706 0.937254901960784 1" />
      </material>
    </visual>
    <collision>
      <origin
        xyz="0 0 0"
        rpy="0 0 0" />
      <geometry>
        <mesh
          filename="package://poppy_torso_v2.urdf/meshes/right_elbow.STL" />
      </geometry>
    </collision>
  </link>
  <joint
    name="right_elbow_joint"
    type="revolute">
    <origin
      xyz="0 -0.0426 -0.0185"
      rpy="-1.5708 2.2204E-16 1.6653E-16" />
    <parent
      link="right_shoulder2" />
    <child
      link="right_elbow" />
    <axis
      xyz="0 0 1" />
    <limit
      effort="0"
      velocity="0" />
  </joint>
  <link
    name="right_elbow2">
    <inertial>
      <origin
        xyz="-0.00340868592241039 0.134711247484355 -0.00503043642723301"
        rpy="0 0 0" />
      <mass
        value="0.124625516627974" />
      <inertia
        ixx="0.000397680389475006"
        ixy="-2.12619437612095E-05"
        ixz="7.26333594597004E-07"
        iyy="4.57040928235963E-05"
        iyz="-1.8682332451256E-05"
        izz="0.000375377777767462" />
    </inertial>
    <visual>
      <origin
        xyz="0 0 0"
        rpy="0 0 0" />
      <geometry>
        <mesh
          filename="package://poppy_torso_v2.urdf/meshes/right_elbow2.STL" />
      </geometry>
      <material
        name="">
        <color
          rgba="0.796078431372549 0.823529411764706 0.937254901960784 1" />
      </material>
    </visual>
    <collision>
      <origin
        xyz="0 0 0"
        rpy="0 0 0" />
      <geometry>
        <mesh
          filename="package://poppy_torso_v2.urdf/meshes/right_elbow2.STL" />
      </geometry>
    </collision>
  </link>
  <joint
    name="right_elbow2_joint"
    type="revolute">
    <origin
      xyz="0 -0.00999999999999998 -0.1064"
      rpy="-1.5707963267949 1.66533453693773E-16 -1.5707963267949" />
    <parent
      link="right_elbow" />
    <child
      link="right_elbow2" />
    <axis
      xyz="0 0 1" />
  </joint>
  <link
    name="right_wrist">
    <inertial>
      <origin
        xyz="-0.0642529300581734 0.0177840040748433 0.0184512292757371"
        rpy="0 0 0" />
      <mass
        value="0.0715975820399687" />
      <inertia
        ixx="3.56821022993205E-05"
        ixy="-1.02049744931556E-05"
        ixz="2.63583417086157E-09"
        iyy="0.000115215206434755"
        iyz="-9.72908851266577E-10"
        izz="0.000116111645694141" />
    </inertial>
    <visual>
      <origin
        xyz="0 0 0"
        rpy="0 0 0" />
      <geometry>
        <mesh
          filename="package://poppy_torso_v2.urdf/meshes/right_wrist.STL" />
      </geometry>
      <material
        name="">
        <color
          rgba="0.796078431372549 0.823529411764706 0.937254901960784 1" />
      </material>
    </visual>
    <collision>
      <origin
        xyz="0 0 0"
        rpy="0 0 0" />
      <geometry>
        <mesh
          filename="package://poppy_torso_v2.urdf/meshes/right_wrist.STL" />
      </geometry>
    </collision>
  </link>
  <joint
    name="right_wrist_joint"
    type="revolute">
    <origin
      xyz="-0.022439 0.141 -0.02248"
      rpy="-1.5708 -2.7756E-16 -1.5708" />
    <parent
      link="right_elbow2" />
    <child
      link="right_wrist" />
    <axis
      xyz="0 0 1" />
    <limit
      effort="0"
      velocity="0" />
  </joint>
  <link
    name="right_end_effector" />
  <joint
    name="right_end_effector_joint"
    type="fixed">
    <origin
      xyz="-0.082791 -0.02673 0.02124"
      rpy="1.5708 -7.1183E-17 3.1416" />
    <parent
      link="right_wrist" />
    <child
      link="right_end_effector" />
    <axis
      xyz="0 0 0" />
  </joint>
  <link
    name="neck">
    <inertial>
      <origin
        xyz="-0.00147486363195594 -2.29735059432586E-05 0.00934455262566064"
        rpy="0 0 0" />
      <mass
        value="0.00677087390469401" />
      <inertia
        ixx="8.3482623769146E-07"
        ixy="2.31762252256955E-10"
        ixz="1.06993581973398E-07"
        iyy="2.96143119089197E-06"
        iyz="1.78774539485729E-11"
        izz="2.68691929886332E-06" />
    </inertial>
    <visual>
      <origin
        xyz="0 0 0"
        rpy="0 0 0" />
      <geometry>
        <mesh
          filename="package://poppy_torso_v2.urdf/meshes/neck.STL" />
      </geometry>
      <material
        name="">
        <color
          rgba="0.796078431372549 0.823529411764706 0.937254901960784 1" />
      </material>
    </visual>
    <collision>
      <origin
        xyz="0 0 0"
        rpy="0 0 0" />
      <geometry>
        <mesh
          filename="package://poppy_torso_v2.urdf/meshes/neck.STL" />
      </geometry>
    </collision>
  </link>
  <joint
    name="neck_joint"
    type="revolute">
    <origin
      xyz="0.0839399999999999 0 0.004979922501418"
      rpy="-1.5707963267949 2.22044604925031E-16 -1.5707963267949" />
    <parent
      link="chest_front" />
    <child
      link="neck" />
    <axis
      xyz="0 0 1" />
  </joint>
  <link
    name="head">
    <inertial>
      <origin
        xyz="-0.0235262061888789 -0.0273909853664446 -6.67430958644667E-05"
        rpy="0 0 0" />
      <mass
        value="0.21637549154107" />
      <inertia
        ixx="0.000453887062747367"
        ixy="-2.2572214608181E-05"
        ixz="-2.47613048704807E-06"
        iyy="0.000473881282434396"
        iyz="-3.20082275517481E-07"
        izz="0.000401890028179113" />
    </inertial>
    <visual>
      <origin
        xyz="0 0 0"
        rpy="0 0 0" />
      <geometry>
        <mesh
          filename="package://poppy_torso_v2.urdf/meshes/head.STL" />
      </geometry>
      <material
        name="">
        <color
          rgba="0.796078431372549 0.823529411764706 0.937254901960784 1" />
      </material>
    </visual>
    <collision>
      <origin
        xyz="0 0 0"
        rpy="0 0 0" />
      <geometry>
        <mesh
          filename="package://poppy_torso_v2.urdf/meshes/head.STL" />
      </geometry>
    </collision>
  </link>
  <joint
    name="head_link"
    type="revolute">
    <origin
      xyz="0 -2.0077E-05 0.02006"
      rpy="-1.5708 3.3541E-16 -1.5708" />
    <parent
      link="neck" />
    <child
      link="head" />
    <axis
      xyz="0 0 1" />
    <limit
      effort="0"
      velocity="0" />
  </joint>
</robot>